Internal Server Error: /products/all/
Traceback (most recent call last):
  File "/Users/edwardmuriuki/.pyenv/versions/3.9.6/lib/python3.9/site-packages/django/template/backends/django.py", line 61, in render
    return self.template.render(context)
  File "/Users/edwardmuriuki/.pyenv/versions/3.9.6/lib/python3.9/site-packages/django/template/base.py", line 175, in render
    return self._render(context)
  File "/Users/edwardmuriuki/.pyenv/versions/3.9.6/lib/python3.9/site-packages/django/template/base.py", line 167, in _render
    return self.nodelist.render(context)
  File "/Users/edwardmuriuki/.pyenv/versions/3.9.6/lib/python3.9/site-packages/django/template/base.py", line 1005, in render
    return SafeString("".join([node.render_annotated(context) for node in self]))
  File "/Users/edwardmuriuki/.pyenv/versions/3.9.6/lib/python3.9/site-packages/django/template/base.py", line 1005, in <listcomp>
    return SafeString("".join([node.render_annotated(context) for node in self]))
  File "/Users/edwardmuriuki/.pyenv/versions/3.9.6/lib/python3.9/site-packages/django/template/base.py", line 966, in render_annotated
    return self.render(context)
  File "/Users/edwardmuriuki/.pyenv/versions/3.9.6/lib/python3.9/site-packages/django/template/loader_tags.py", line 132, in render
    compiled_parent = self.get_parent(context)
  File "/Users/edwardmuriuki/.pyenv/versions/3.9.6/lib/python3.9/site-packages/django/template/loader_tags.py", line 129, in get_parent
    return self.find_template(parent, context)
  File "/Users/edwardmuriuki/.pyenv/versions/3.9.6/lib/python3.9/site-packages/django/template/loader_tags.py", line 107, in find_template
    template, origin = context.template.engine.find_template(
  File "/Users/edwardmuriuki/.pyenv/versions/3.9.6/lib/python3.9/site-packages/django/template/engine.py", line 161, in find_template
    raise TemplateDoesNotExist(name, tried=tried)
django.template.exceptions.TemplateDoesNotExist: newbase.html

The above exception was the direct cause of the following exception:

Traceback (most recent call last):
  File "/Users/edwardmuriuki/.pyenv/versions/3.9.6/lib/python3.9/site-packages/django/core/handlers/exception.py", line 55, in inner
    response = get_response(request)
  File "/Users/edwardmuriuki/.pyenv/versions/3.9.6/lib/python3.9/site-packages/django/core/handlers/base.py", line 220, in _get_response
    response = response.render()
  File "/Users/edwardmuriuki/.pyenv/versions/3.9.6/lib/python3.9/site-packages/django/template/response.py", line 114, in render
    self.content = self.rendered_content
  File "/Users/edwardmuriuki/.pyenv/versions/3.9.6/lib/python3.9/site-packages/django/template/response.py", line 92, in rendered_content
    return template.render(context, self._request)
  File "/Users/edwardmuriuki/.pyenv/versions/3.9.6/lib/python3.9/site-packages/django/template/backends/django.py", line 63, in render
    reraise(exc, self.backend)
  File "/Users/edwardmuriuki/.pyenv/versions/3.9.6/lib/python3.9/site-packages/django/template/backends/django.py", line 84, in reraise
    raise new from exc
django.template.exceptions.TemplateDoesNotExist: newbase.html
